:c:func:`_PyErr_ChainStackItem` no longer normalizes ``exc_info`` (including setting the traceback on the exception instance) because ``exc_info`` is always normalized.